{
    "name": "搭建现实框架",
    "icon": "kubejs:reality_controller_running",
    "category": "patchouli:multiblock",
    "pages": [
	    {
            "type": "patchouli:spotlight",
            "item": "kubejs:reality_controller_running",
			"title": "建造现实框架",
			"text": "你可以用这本书可视化现实框架的多方块结构，大大减轻搭建难度。$(br2)重点注意，现实控制器可以放置在任意底边的中央，现实充能器的能量每次使用后会被消耗。"
		},
		{
			"type": "patchouli:multiblock",
			"multiblock": {
			"pattern": [
				[ "FFFFFFFFF", "F       F", "F       F",  "F       F",  "F       F",  "F       F",  "F       F",  "F       F",  "FFFFFFFFF" ], 
				[ "F       F", "         ", "         ",  "         ",  "         ",  "         ",  "         ",  "         ",  "F       F" ], 
				[ "F       F", "         ", "         ",  "         ",  "         ",  "         ",  "         ",  "         ",  "F       F" ], 
				[ "F       F", "         ", "         ",  "         ",  "         ",  "         ",  "         ",  "         ",  "F       F" ], 
				[ "F       F", "         ", "         ",  "         ",  "         ",  "         ",  "         ",  "         ",  "F       F" ], 
				[ "F       F", "         ", "         ",  "         ",  "         ",  "         ",  "         ",  "         ",  "F       F" ], 
				[ "F       F", "         ", "         ",  "         ",  "         ",  "         ",  "         ",  "         ",  "F       F" ], 
				[ "F       F", "         ", "         ",  "         ",  "B        ",  "         ",  "         ",  "         ",  "F       F" ], 
				[ "FFFFFFFFF", "F       F", "F       F",  "F       F",  "C   0   F",  "F       F",  "F       F",  "F       F",  "FFFFFFFFF" ]

			],
			"mapping": {
				"F": "kubejs:reality_frame",
				"C": "kubejs:reality_controller",
				"B": "kubejs:reality_charge"
			},
			"symmetrical": true
			}
		}
]}